Workbook

Sheet Executive Dashboard
A1: AGI ERP DIGITIZATION CONTROL TOWER
A2: Evidence-based enterprise transformation baseline — project completion is not treated as process maturity
A3: As of 14 Sep 2026 | Current evidence position: five calibration design packs complete; O2C provisionally reviewed as S1–S2 / E2 Candidate; no wave yet verified with E3+ production execution evidence.
A5: CALIBRATION WAVES DESIGNED | D5: PROVISIONAL EVIDENCE REVIEWS | G5: LIVE-CALIBRATED WAVES (E3+) | J5: O2C PILOT KPIs | M5: O2C EVENT SCHEMA FIELDS
A6: =COUNTA('Calibration Waves'!B2:B6) -> 5 | D6: =COUNTIF('Calibration Waves'!F2:F6,"*provisional evidence calibration completed*") -> 1 | G6: 0 | J6: =COUNTA('O2C Pilot KPI Baseline'!A2:A16) -> 15 | M6: =COUNTA('O2C Event Schema'!A2:A34) -> 33
A7: 5 / 5 design packs complete | D7: Wave 1 O2C only | G7: Production extraction has not started | J7: Baseline values remain pending | M7: 33-field canonical event schema + 59 normalized O2C activities
A10: TRANSFORMATION CALIBRATION PIPELINE
A11: 1. Process Registry / Taxonomy | D11: 2. Calibration Design Packs | G11: 3. Provisional Evidence Review | J11: 4. Live E3 Calibration | M11: 5. Verified E4/E5 Outcomes
A12: COMPLETE | D12: 5 / 5 COMPLETE | G12: 1 / 5 COMPLETE | J12: 0 / 5 | M12: 0 / 5
A13: Enterprise L0-L6 taxonomy and process registry established | D13: O2C, S2P, D2POD, A2P and P2P packs complete | G13: O2C evidence review completed provisionally | J13: Requires production event extraction | M13: Requires measured baseline and verified business value
A15: DEPARTMENTAL TRANSFORMATION PORTFOLIO
A16: # | B16: Functional Wing | D16: Journey | F16: Design Pack | H16: Evidence Review | J16: Live Calibration | L16: Current State / Evidence | N16: Next Action
A17: 1 | B17: ='Dashboard Inputs'!A2 -> Sales | D17: ='Dashboard Inputs'!B2 -> Order-to-Cash | F17: ='Dashboard Inputs'!D2 -> Complete | H17: ='Dashboard Inputs'!E2 -> Complete | J17: ='Dashboard Inputs'!F2 -> Pending | L17: ='Dashboard Inputs'!G2&" / "&'Dashboard Inputs'!H2 -> S1-S2 (provisional) / E2 Candidate | N17: ='Dashboard Inputs'!K2 -> Treat AOPL only as the provisional first-to-check. Issue its P0 requests DR-O2C-01/02/03/04/07/09/10, verify the latest complete 30-day Sales Eco→BC→Logistics→Finance chain, and select a pilot only after all 7 mandatory gates pass; if AOPL fails a gate, validate AGL next.
A18: 2 | B18: ='Dashboard Inputs'!A3 -> SCM | D18: ='Dashboard Inputs'!B3 -> Source-to-Pay | F18: ='Dashboard Inputs'!D3 -> Complete | H18: ='Dashboard Inputs'!E3 -> Pending | J18: ='Dashboard Inputs'!F3 -> Pending | L18: ='Dashboard Inputs'!G3&" / "&'Dashboard Inputs'!H3 -> Not calibrated / E1-E2 Design Evidence | N18: ='Dashboard Inputs'!K3 -> Run evidence review and extract demand→vendor→RFQ→PO→GRN/QC→invoice→payment events once live evidence is available.
A19: 3 | B19: ='Dashboard Inputs'!A4 -> Logistics | D19: ='Dashboard Inputs'!B4 -> Delivery-to-POD | F19: ='Dashboard Inputs'!D4 -> Complete | H19: ='Dashboard Inputs'!E4 -> Pending | J19: ='Dashboard Inputs'!F4 -> Pending | L19: ='Dashboard Inputs'!G4&" / "&'Dashboard Inputs'!H4 -> Not calibrated / E1-E2 Design Evidence | N19: ='Dashboard Inputs'!K4 -> Validate actual digital coverage from DO readiness through POD and reconciliation using live trip/dispatch events.
A20: 4 | B20: ='Dashboard Inputs'!A5 -> HR | D20: ='Dashboard Inputs'!B5 -> Attendance-to-Payroll | F20: ='Dashboard Inputs'!D5 -> Complete | H20: ='Dashboard Inputs'!E5 -> Pending | J20: ='Dashboard Inputs'!F5 -> Pending | L20: ='Dashboard Inputs'!G5&" / "&'Dashboard Inputs'!H5 -> Not calibrated / E1 Design Evidence | N20: ='Dashboard Inputs'!K5 -> Validate master data, attendance-device flow, payroll run, bank response and payroll→BC posting using consecutive payroll periods.
A21: 5 | B21: ='Dashboard Inputs'!A6 -> Production | D21: ='Dashboard Inputs'!B6 -> Plan-to-Produce | F21: ='Dashboard Inputs'!D6 -> Complete | H21: ='Dashboard Inputs'!E6 -> Pending | J21: ='Dashboard Inputs'!F6 -> Pending | L21: ='Dashboard Inputs'!G6&" / "&'Dashboard Inputs'!H6 -> Not calibrated / E1 Design Evidence | N21: ='Dashboard Inputs'!K6 -> Sample production orders end-to-end, including materials, operation events, QC, FG, scrap/by-product and costing reconciliation.
A22: 6 | B22: ='Dashboard Inputs'!A7 -> Finance | D22: ='Dashboard Inputs'!B7 -> Record-to-Report | F22: ='Dashboard Inputs'!D7 -> Registry baseline | H22: ='Dashboard Inputs'!E7 -> Pending | J22: ='Dashboard Inputs'!F7 -> Pending | L22: ='Dashboard Inputs'!G7&" / "&'Dashboard Inputs'!H7 -> Not calibrated / E1 Design Evidence | N22: ='Dashboard Inputs'!K7 -> Create R2R calibration pack and sample actual close, reconciliation, posting and reporting evidence.
A23: 7 | B23: ='Dashboard Inputs'!A8 -> Quality Control | D23: ='Dashboard Inputs'!B8 -> Quality-to-Release | F23: ='Dashboard Inputs'!D8 -> Registry baseline | H23: ='Dashboard Inputs'!E8 -> Pending | J23: ='Dashboard Inputs'!F8 -> Pending | L23: ='Dashboard Inputs'!G8&" / "&'Dashboard Inputs'!H8 -> Not calibrated / E1 Composite Evidence | N23: ='Dashboard Inputs'!K8 -> Create standalone QC discovery/calibration pack and validate incoming, in-process and final inspection evidence.
A24: 8 | B24: ='Dashboard Inputs'!A9 -> Inventory / Warehouse | D24: ='Dashboard Inputs'!B9 -> Inventory-to-Fulfilment | F24: ='Dashboard Inputs'!D9 -> Registry baseline | H24: ='Dashboard Inputs'!E9 -> Pending | J24: ='Dashboard Inputs'!F9 -> Pending | L24: ='Dashboard Inputs'!G9&" / "&'Dashboard Inputs'!H9 -> Not calibrated / E1-E2 Candidate | N24: ='Dashboard Inputs'!K9 -> Create dedicated inventory calibration pack and validate stock accuracy, reservation, movement, cycle count and inventory→GL evidence.
A27: EXECUTIVE INSIGHTS
A28: Evidence discipline | E28: Current bottleneck | I28: Immediate action | M28: Next promotion gate
A29: Jira Done / configured capability supports E2 only. It does not prove execution, adoption or realized value. | E29: No unified production O2C event log yet, so cycle time, variants, STP and human dependency are not verified. | I29: Start Wave 1 event extraction across Sales Eco, Business Central and Logistics using the O2C Event Schema and Source-to-Field Mapping. | M29: E3 = real production cases; E4 = repeatable measured KPIs/variants; E5 = verified improvement against baseline.
I34: CONTROL TOWER STATUS
I35: Metric | K35: Current Position | M35: Implication
I36: Project status visibility | K36: Available | M36: ERP plan/Jira show delivery progress, not transformation maturity
I37: Process taxonomy | K37: Established | M37: Stable L0-L6 process identity now exists
I38: O2C evidence review | K38: Provisional E2 Candidate | M38: Ready for production event extraction
I39: Unified event log | K39: Not yet built | M39: Prevents verified cross-system KPI reporting
I40: Verified business outcomes | K40: Baseline pending | M40: No productivity, cycle-time or cost claim should be reported as realized yet
A42: O2C PILOT SBU SELECTION
A43: Current Position | D43: Provisional First-to-Check | G43: Selection Gate | J43: Why Not Selected Yet | M43: Immediate Next Action
A44: Pilot selection pending live data evidence | D44: AOPL — not selected | G44: 7/7 mandatory gates must pass | J44: Project-plan chronology and Jira/email activity do not prove end-to-end production lineage, adoption or reconciled source coverage. | M44: Issue P0 data requests and validate Sales Eco → BC → Logistics → Finance coverage before scoring candidates.

Sheet Dashboard Inputs
A1: Wing | B1: Journey | C1: Functional Wings | D1: Design Pack | E1: Provisional Evidence Review | F1: Live Calibration | G1: Provisional Current State | H1: Provisional Evidence Level | I1: Calibration Readiness | J1: Current Evidence Position | K1: Next Action | L1: Primary Owner(s) | M1: Primary Evidence Source | N1: Last Updated
A2: Sales | B2: Order-to-Cash | C2: Sales → Inventory → Logistics → Finance | D2: Complete | E2: Complete | F2: Pending | G2: S1-S2 (provisional) | H2: E2 Candidate | I2: High | J2: Implementation/QA stabilization evidence exists; production execution baseline is not yet verified. The 33-field event schema, 59-activity dictionary, source mapping, extraction runbook, data-request pack, 15 quality gates, evidence-gated SBU selection matrix and intake tracker are now prepared for Wave 1. | K2: Treat AOPL only as the provisional first-to-check. Issue its P0 requests DR-O2C-01/02/03/04/07/09/10, verify the latest complete 30-day Sales Eco→BC→Logistics→Finance chain, and select a pilot only after all 7 mandatory gates pass; if AOPL fails a gate, validate AGL next. | L2: Sales + Product + Finance + Logistics | M2: O2C Calibration Register; Source-to-Field Mapping; Extraction Runbook; Data Request Pack; Data Quality Gates; Pilot SBU Selection; Pilot Evidence Intake; BSES Jira | N2: 2026-09-15
A3: SCM | B3: Source-to-Pay | C3: SCM → Inventory/QC → Finance | D3: Complete | E3: Pending | F3: Pending | G3: Not calibrated | H3: E1-E2 Design Evidence | I3: Medium-High | J3: Detailed process catalogue and fit-gap/UAT evidence exist; actual production execution is not yet calibrated. | K3: Run evidence review and extract demand→vendor→RFQ→PO→GRN/QC→invoice→payment events once live evidence is available. | L3: SCM + ERP Team + Finance | M3: Signed SCM SDD; SCM BC annexes; S2P design pack | N3: 2026-09-14
A4: Logistics | B4: Delivery-to-POD | C4: Sales → Logistics → Inventory → Finance | D4: Complete | E4: Pending | F4: Pending | G4: Not calibrated | H4: E1-E2 Design Evidence | I4: Medium-High | J4: Detailed logistics target process exists, including loading, gate, dispatch, POD and exception handling; live telemetry is not yet verified. | K4: Validate actual digital coverage from DO readiness through POD and reconciliation using live trip/dispatch events. | L4: Logistics + ERP/Product + Warehouse | M4: Logistics PRD/SDD; D2POD design pack | N4: 2026-09-14
A5: HR | B5: Attendance-to-Payroll | C5: HR → Finance | D5: Complete | E5: Pending | F5: Pending | G5: Not calibrated | H5: E1 Design Evidence | I5: Medium-High | J5: HR scope, WBS, integrations and process requirements are defined; production attendance/payroll evidence has not been calibrated. | K5: Validate master data, attendance-device flow, payroll run, bank response and payroll→BC posting using consecutive payroll periods. | L5: HR + Payroll + Finance + ERP Team | M5: HR Module Project Management Annexes; A2P design pack | N5: 2026-09-14
A6: Production | B6: Plan-to-Produce | C6: Planning → Production → QC → Inventory → Finance | D6: Complete | E6: Pending | F6: Pending | G6: Not calibrated | H6: E1 Design Evidence | I6: Medium | J6: Production process and AIL variant are mapped, but shop-floor, QC, genealogy, instrumentation and costing evidence still require live validation. | K6: Sample production orders end-to-end, including materials, operation events, QC, FG, scrap/by-product and costing reconciliation. | L6: Production + QC + Inventory + Finance + ERP Team | M6: Production BRD/Data Record; P2P design pack | N6: 2026-09-14
A7: Finance | B7: Record-to-Report | C7: Finance / Accounting | D7: Registry baseline | E7: Pending | F7: Pending | G7: Not calibrated | H7: E1 Design Evidence | I7: Medium | J7: Finance SDD defines AP, AR, bank, FA, close and controls; no dedicated live R2R calibration wave has yet been run. | K7: Create R2R calibration pack and sample actual close, reconciliation, posting and reporting evidence. | L7: Finance + ERP Team | M7: 04.5 Accounts & Finance SDD; Process Registry | N7: 2026-09-14
A8: Quality Control | B8: Quality-to-Release | C8: QC → Production/Inventory | D8: Registry baseline | E8: Pending | F8: Pending | G8: Not calibrated | H8: E1 Composite Evidence | I8: Low-Medium | J8: QC requirements are evidenced through Production and SCM artefacts; standalone QC operating evidence is incomplete. | K8: Create standalone QC discovery/calibration pack and validate incoming, in-process and final inspection evidence. | L8: QC + Production + SCM + ERP Team | M8: Production/SCM quality requirements; Process Registry | N8: 2026-09-14
A9: Inventory / Warehouse | B9: Inventory-to-Fulfilment | C9: Inventory → Warehouse → Sales/Production/Logistics | D9: Registry baseline | E9: Pending | F9: Pending | G9: Not calibrated | H9: E1-E2 Candidate | I9: Medium | J9: Inventory design covers item/location/bin, receipts, transfers, picks, counts, costing and reconciliation; operational migration/reconciliation evidence remains incomplete. | K9: Create dedicated inventory calibration pack and validate stock accuracy, reservation, movement, cycle count and inventory→GL evidence. | L9: Inventory/Warehouse + Finance + ERP Team | M9: Inventory SDD; ERP plan/migration evidence; Process Registry | N9: 2026-09-14
A11: Calibration Stage | B11: Completed Waves | C11: Total Waves | D11: Completion %
A12: Design Packs Complete | B12: 5 | C12: 5 | D12: =B12/C12 -> 1
A13: Provisional Evidence Review | B13: 1 | C13: 5 | D13: =B13/C13 -> 0.2
A14: Live E3 Execution Calibration | B14: 0 | C14: 5 | D14: =B14/C14 -> 0
A15: Measured E4 Baseline | B15: 0 | C15: 5 | D15: =B15/C15 -> 0
A16: Outcome E5 Verification | B16: 0 | C16: 5 | D16: =B16/C16 -> 0

Sheet README
A1: AGI Enterprise Process Registry v1
A2: Purpose | B2: Create one evidence-based canonical process registry for management transformation visibility across ERP digitization, workflow automation, AI assistance and bounded agentic execution.
A3: Version | B3: v1 - 2026-09-14
A4: Scope | B4: Sales; Finance & Accounts; SCM / Procurement / Commercial; Inventory & Warehouse; Logistics; Production / Manufacturing; Quality Control; Human Resources.
A5: Important | B5: The registry is a taxonomy baseline. Current S-state and E-level fields are provisional until calibrated against production execution and outcome evidence.
A6: Core Rule 1 | B6: Use one canonical process with organization/SBU variants instead of duplicating the same process per company.
A7: Core Rule 2 | B7: Keep functional hierarchy (L0-L6) separate from horizontal end-to-end value streams.
A8: Core Rule 3 | B8: Transformation maturity should ultimately be measured at L5/L6 and rolled up to L3; L3 averages can hide human/manual decisions.
A9: Core Rule 4 | B9: S5 agentic autonomy is not a universal target. The right target depends on business value, control criticality, safety, legal constraints, data quality and reversibility.
A10: Core Rule 5 | B10: Do not infer current maturity from BRD/FRD/SDD completeness, configuration, or schedule progress alone.
A11: Registry Rows | B11: 94

Sheet Process Registry
A1: Process ID | B1: L0 Enterprise | C1: L1 Organization / SBU | D1: L2 Functional Wing | E1: L3 Process Group | F1: Representative L4 Sub-processes | G1: E2E Value Stream | H1: Current State (Provisional) | I1: Target State (Provisional) | J1: Evidence Level (Provisional) | K1: Calibration Status | L1: Management Note | M1: Source Title | N1: Source URL
A2: SAL-01 | B2: AGI | C2: Canonical / all applicable SBUs | D2: Sales | E2: Customer & Channel Management | F2: Customer onboarding; Customer Type; dealer/retailer/site relationship; lifecycle/status | G2: O2C | H2: Candidate S1-S2; calibration required | I2: S2 | J2: E2 | K2: Not calibrated | L2: Design/product/configuration evidence exists; require production usage/outcome evidence before E3/E4. | M2: Business Process Mapping Document - Primary Sales_UPDATED_SDD | N2: https://docs.google.com/document/d/1IoV-RaOxb83z2IttGlRKy863G_pckAGUegBqnRkemgc/edit?usp=drivesdk
A3: SAL-02 | B3: AGI | C3: Canonical / all applicable SBUs | D3: Sales | E3: Territory & Sales Organization Management | F3: Territory hierarchy; salesperson assignment; RC assignment; organization/user access | G3: O2C | H3: Candidate S1-S2; calibration required | I3: S2 | J3: E2 | K3: Not calibrated | L3: Design/product/configuration evidence exists; require production usage/outcome evidence before E3/E4. | M3: Business Process Mapping Document - Primary Sales_UPDATED_SDD | N3: https://docs.google.com/document/d/1IoV-RaOxb83z2IttGlRKy863G_pckAGUegBqnRkemgc/edit?usp=drivesdk
A4: SAL-03 | B4: AGI | C4: Canonical / all applicable SBUs | D4: Sales | E4: Lead, Site & Opportunity Management | F4: Site identification; influencer mapping; opportunity qualification; conversion/loss | G4: L2O | H4: Candidate S1-S2; calibration required | I4: S3 | J4: E2 | K4: Not calibrated | L4: Design/product/configuration evidence exists; require production usage/outcome evidence before E3/E4. | M4: Business Process Mapping Document - Primary Sales_UPDATED_SDD | N4: https://docs.google.com/document/d/1IoV-RaOxb83z2IttGlRKy863G_pckAGUegBqnRkemgc/edit?usp=drivesdk
A5: SAL-04 | B5: AGI | C5: Canonical / all applicable SBUs | D5: Sales | E5: Quotation Management | F5: Quote creation; pricing; validity; approval; conversion | G5: O2C | H5: Candidate S1-S2; calibration required | I5: S2 | J5: E2 | K5: Not calibrated | L5: Design/product/configuration evidence exists; require production usage/outcome evidence before E3/E4. | M5: Business Process Mapping Document - Primary Sales_UPDATED_SDD | N5: https://docs.google.com/document/d/1IoV-RaOxb83z2IttGlRKy863G_pckAGUegBqnRkemgc/edit?usp=drivesdk
A6: SAL-05 | B6: AGI | C6: Canonical / all applicable SBUs | D6: Sales | E6: Order Management | F6: Customer order; Sales Order creation; validation; approval/rejection/resubmission | G6: O2C | H6: Candidate S1-S2; calibration required | I6: S2 | J6: E2 | K6: Not calibrated | L6: Design/product/configuration evidence exists; require production usage/outcome evidence before E3/E4. | M6: Business Process Mapping Document - Primary Sales_UPDATED_SDD | N6: https://docs.google.com/document/d/1IoV-RaOxb83z2IttGlRKy863G_pckAGUegBqnRkemgc/edit?usp=drivesdk
A7: SAL-06 | B7: AGI | C7: Canonical / all applicable SBUs | D7: Sales | E7: Pricing, Discount & Commercial Control | F7: Price determination; discount; scheme; approval; exception | G7: O2C | H7: Candidate S1-S2; calibration required | I7: S2 | J7: E2 | K7: Not calibrated | L7: Design/product/configuration evidence exists; require production usage/outcome evidence before E3/E4. | M7: Business Process Mapping Document - Primary Sales_UPDATED_SDD | N7: https://docs.google.com/document/d/1IoV-RaOxb83z2IttGlRKy863G_pckAGUegBqnRkemgc/edit?usp=drivesdk
A8: SAL-07 | B8: AGI | C8: Canonical / all applicable SBUs | D8: Sales | E8: Credit Management | F8: Credit-limit check; RC-based credit; holds; override/escalation | G8: O2C | H8: Candidate S1-S2; calibration required | I8: S2 | J8: E2 | K8: Not calibrated | L8: Design/product/configuration evidence exists; require production usage/outcome evidence before E3/E4. | M8: Business Process Mapping Document - Primary Sales_UPDATED_SDD | N8: https://docs.google.com/document/d/1IoV-RaOxb83z2IttGlRKy863G_pckAGUegBqnRkemgc/edit?usp=drivesdk
A9: SAL-08 | B9: AGI | C9: Canonical / all applicable SBUs | D9: Sales | E9: Fulfilment Coordination | F9: DO initiation; DN status; partial delivery; substitution; outstanding balance | G9: O2C / I2F | H9: Candidate S1-S2; calibration required | I9: S2 | J9: E2 | K9: Not calibrated | L9: Design/product/configuration evidence exists; require production usage/outcome evidence before E3/E4. | M9: Business Process Mapping Document - Primary Sales_UPDATED_SDD | N9: https://docs.google.com/document/d/1IoV-RaOxb83z2IttGlRKy863G_pckAGUegBqnRkemgc/edit?usp=drivesdk
A10: SAL-09 | B10: AGI | C10: Canonical / all applicable SBUs | D10: Sales | E10: Billing & Invoice Coordination | F10: Invoice trigger; invoice reference; Sales Eco/BC status synchronization | G10: O2C | H10: Candidate S1-S2; calibration required | I10: S2 | J10: E2 | K10: Not calibrated | L10: Design/product/configuration evidence exists; require production usage/outcome evidence before E3/E4. | M10: Business Process Mapping Document - Primary Sales_UPDATED_SDD | N10: https://docs.google.com/document/d/1IoV-RaOxb83z2IttGlRKy863G_pckAGUegBqnRkemgc/edit?usp=drivesdk
A11: SAL-10 | B11: AGI | C11: Canonical / all applicable SBUs | D11: Sales | E11: Collection Management | F11: Money receipt; approval/rejection; ledger synchronization; reconciliation | G11: O2C | H11: Candidate S1-S2; calibration required | I11: S2 | J11: E2 | K11: Not calibrated | L11: Design/product/configuration evidence exists; require production usage/outcome evidence before E3/E4. | M11: Business Process Mapping Document - Primary Sales_UPDATED_SDD | N11: https://docs.google.com/document/d/1IoV-RaOxb83z2IttGlRKy863G_pckAGUegBqnRkemgc/edit?usp=drivesdk
A12: SAL-11 | B12: AGI | C12: Canonical / all applicable SBUs | D12: Sales | E12: Sales Return & Adjustment | F12: Return request; DN validation; approval; inventory/financial adjustment | G12: O2C | H12: Candidate S1-S2; calibration required | I12: S2 | J12: E2 | K12: Not calibrated | L12: Design/product/configuration evidence exists; require production usage/outcome evidence before E3/E4. | M12: Business Process Mapping Document - Primary Sales_UPDATED_SDD | N12: https://docs.google.com/document/d/1IoV-RaOxb83z2IttGlRKy863G_pckAGUegBqnRkemgc/edit?usp=drivesdk
... A95: HR-11 | B95: AGI | C95: Canonical / all applicable SBUs | D95: Human Resources | E95: Performance Management | F95: KPI/OKR; scorecard; competency; review | G95: P2PPL | H95: TBD | I95: S3 | J95: E1 | K95: Not calibrated | L95: Discovery/annex baseline exists; current partner build, production use and payroll execution need evidence. | M95: hr_module_project_management_annexes_2026-07-18 | N95: https://docs.google.com/spreadsheets/d/1XfHiOhLTJvGO_VKHyitZ8ijc_og8feRt5wAfyi8PC48/edit?usp=drivesdk

Sheet Hierarchy & Coding
A1: Level | B1: Definition | C1: Example | D1: Rule
A2: L0 | B2: Enterprise | C2: AGI | D2: Single enterprise identity.
A3: L1 | B3: Organization / SBU | C3: AIL / ACL / ACSL / AOPL / AGL | D3: Attach organization variants to canonical processes; do not duplicate taxonomy unnecessarily.
A4: L2 | B4: Functional Wing | C4: Sales | D4: Department / functional ownership view.
A5: L3 | B5: Process Group | C5: Order Management | D5: Stable canonical process group used for management aggregation.
A6: L4 | B6: Sub-process | C6: Sales Order Processing | D6: Functional decomposition of L3.
A7: L5 | B7: Activity | C7: Validate Sales Order | D7: Operational activity where human/system contribution can be measured.
A8: L6 | B8: Task / Decision | C8: Check customer, RC, price, credit, stock and approval | D8: Atomic task/decision for automation and control analysis.
A10: Dimension | B10: Definition | C10: Examples | D10: Rule
A11: E2E Value Stream | B11: Horizontal process journey spanning multiple wings | C11: O2C; S2P; P2P; Q2R; I2F; D2POD; R2R; H2R | D11: Use as a separate dimension rather than forcing an end-to-end journey into L3.
A12: Canonical process variant | B12: Same process across legal entities/SBUs | C12: AGI.SALES.ORDER.SALES_ORDER + AIL/ACL/AGL variants | D12: One canonical process, multiple organization-specific variants.

Sheet Transformation States
A1: State | B1: Name | C1: Definition | D1: Typical Human Role | E1: Important Guardrail
A2: S0 | B2: Manual / Fragmented | C2: Work is performed through paper, spreadsheets, email, phone, memory or disconnected tools. | D2: Performs most execution and decisions. | E2: Baseline only; identify control/data risks.
A3: S1 | B3: Digitized / System of Record | C3: Process is captured in an approved system with structured data and traceability. | D3: Executes process in system. | E3: Digitized does not mean automated or adopted.
A4: S2 | B4: Workflow / Rules Automated | C4: Deterministic validations, routing, calculations, integrations and approvals are automated. | D4: Handles exceptions and required approvals. | E4: Rules and SoD remain explicit.
A5: S3 | B5: AI-assisted / Copilot | C5: AI recommends, summarizes, predicts or detects anomalies while humans retain decision authority. | D5: Reviews/accepts/rejects AI output. | E5: Require evidence quality, explainability and human accountability.
A6: S4 | B6: Agent-operated with Human Approval / Supervision | C6: Agent performs multi-step execution but material decisions/actions require human approval or active supervision. | D6: Approves/supervises exceptions and high-impact actions. | E6: Use only where controls, observability and rollback are adequate.
A7: S5 | B7: Agentic / Autonomous within Guardrails | C7: Agent autonomously executes an approved bounded process and escalates exceptions. | D7: Defines guardrails and handles escalations. | E7: Not a universal target. Safety, financial, legal and control-critical processes may optimally stop at S2-S4.

Sheet Evidence Levels
A1: Level | B1: Name | C1: Minimum Evidence Standard | D1: Use in Management Reporting
A2: E0 | B2: No evidence | C2: Statement, assumption or undocumented claim only. | D2: Do not use as maturity fact.
A3: E1 | B3: Design evidence | C3: Approved BRD/FRD/SDD/process map/config specification. | D3: Shows intended design, not actual execution.
A4: E2 | B4: Build / configuration evidence | C4: Working build, configuration, test environment, UAT artifact, integration proof or prototype. | D4: Shows capability exists; adoption/production outcome not proven.
A5: E3 | B5: Production execution evidence | C5: Production transactions/logs demonstrate process is live and repeatedly executed. | D5: Eligible for verified current-state reporting.
A6: E4 | B6: Outcome / adoption evidence | C6: Usage/adoption metrics, cycle-time, exception, quality or productivity outcomes demonstrate operational value. | D6: Eligible for realized-benefit reporting.
A7: E5 | B7: Controlled / audited evidence | C7: Sustained outcomes plus verified control effectiveness, audit trail, governance and exception handling. | D7: Highest confidence for autonomous/agentic operating-state claims.

Sheet Calibration Waves
A1: Priority | B1: Journey | C1: Functional Wings | D1: Reason to Start | E1: Calibration Output | F1: Wave Status
A2: 1 | B2: Order-to-Cash | C2: Sales -> Inventory -> Logistics -> Finance | D2: Strongest existing digital footprint and clear management visibility. | E2: Actual process -> systems -> human touches -> KPI baseline -> S-state -> E-level -> friction -> controls -> target -> opportunity -> readiness -> business case | F2: Wave 1 provisional evidence calibration completed; live production event extraction pending
A3: 2 | B3: Source-to-Pay | C3: SCM -> Inventory/QC -> Finance | D3: Strong catalogue with material control and manual handoffs. | E3: Same calibration pack | F3: Wave 2 design pack created; execution calibration pending
A4: 3 | B4: Delivery-to-POD | C4: Sales -> Logistics -> Inventory -> Finance | D4: Highly visible manual-to-digital journey with measurable exceptions and reconciliation. | E4: Same calibration pack | F4: Wave 3 design pack created; execution calibration pending
A5: 4 | B5: Attendance-to-Payroll | C5: HR -> Finance | D5: Clear measurable productivity, accuracy and control outcome. | E5: Same calibration pack | F5: Wave 4 design pack created; execution calibration pending
A6: 5 | B6: Plan-to-Produce | C6: Sales/Planning -> Production -> QC -> Inventory -> Finance | D6: High manufacturing transformation value; requires strong control discipline. | E6: Same calibration pack | F6: Wave 5 design pack created; execution calibration pending

Sheet Field Dictionary
A1: Field | B1: Purpose / Definition | C1: Level / Type
A2: Process ID | B2: Stable enterprise identifier for the canonical process. | C2: Control
A3: L0-L6 | B3: Hierarchical process decomposition from enterprise to task/decision. | C3: Taxonomy
A4: E2E Value Stream ID | B4: Horizontal cross-functional journey link. | C4: Dimension
A5: Organization | B5: Legal entity/SBU where variant executes. | C5: Dimension
A6: Process Variant | B6: Organization-specific method or policy variant. | C6: Dimension
A7: Business Process Owner | B7: Accountable for business outcome. | C7: Governance
A8: Transformation Owner | B8: Accountable for transformation delivery. | C8: Governance
A9: Control Owner | B9: Accountable for risk/control design and operation. | C9: Governance
A10: Data Owner | B10: Accountable for source/master data quality. | C10: Governance
A11: System(s) | B11: Applications/services used by the process. | C11: Technology
A12: System of Record | B12: Authoritative source of truth. | C12: Technology
... A29: Evidence Link | B29: Direct link to transaction/log/config/SOP/UAT/control evidence. | C29: Evidence

Sheet Sources
A1: Source Type | B1: Functional Wing / Use | C1: Source Title | D1: URL | E1: Evidence Role
A2: Project / design evidence | B2: Sales | C2: Business Process Mapping Document - Primary Sales_UPDATED_SDD | D2: https://docs.google.com/document/d/1IoV-RaOxb83z2IttGlRKy863G_pckAGUegBqnRkemgc/edit?usp=drivesdk | E2: Baseline taxonomy and/or current-state evidence; does not by itself prove production maturity.
A3: Project / design evidence | B3: Finance & Accounts | C3: 04.5-ACCOUNTS-FINANCE-SDD | D3: https://docs.google.com/document/d/1opp2b-tGrMR5YcZ5IZfIjdlIIbNANJ3pPrJsKcnq5Rs/edit?usp=drivesdk | E3: Baseline taxonomy and/or current-state evidence; does not by itself prove production maturity.
A4: Project / design evidence | B4: SCM / Procurement / Commercial | C4: SCM - Signed SDD | D4: https://docs.google.com/document/d/127YQA_Z0zcKBMCFBa4ZgW_kmnExCMgfpheJ_DeoXFmw/edit?usp=drivesdk | E4: Baseline taxonomy and/or current-state evidence; does not by itself prove production maturity.
A5: Project / design evidence | B5: Inventory & Warehouse | C5: 04.1-INVENTORY-MANAGEMENT-SDD | D5: https://docs.google.com/document/d/1eGvAn9ZvGrCKaBnvot_iqCkITzAsJlsNsOteIiyCT58/edit?usp=drivesdk | E5: Baseline taxonomy and/or current-state evidence; does not by itself prove production maturity.
A6: Project / design evidence | B6: Logistics | C6: Logistics Module SDD | D6: https://docs.google.com/document/d/1doGDuain3lxIApXJtGNkRmL4FIkb1EphJ_IGoSFXJQ4/edit?usp=drivesdk | E6: Baseline taxonomy and/or current-state evidence; does not by itself prove production maturity.
A7: Project / design evidence | B7: Production / Manufacturing | C7: Business Requirement Document: Production Module (AIL) | D7: https://docs.google.com/document/d/1JZeibH6jDWNLybYCgJMq-fEYwidL32H4_BTkQFD0Ozw/edit?usp=drivesdk | E7: Baseline taxonomy and/or current-state evidence; does not by itself prove production maturity.
A8: Project / design evidence | B8: Quality Control | C8: Business Requirement Document: Production Module (AIL) - composite QC evidence | D8: https://docs.google.com/document/d/1JZeibH6jDWNLybYCgJMq-fEYwidL32H4_BTkQFD0Ozw/edit?usp=drivesdk | E8: Baseline taxonomy and/or current-state evidence; does not by itself prove production maturity.
A9: Project / design evidence | B9: Human Resources | C9: hr_module_project_management_annexes_2026-07-18 | D9: https://docs.google.com/spreadsheets/d/1XfHiOhLTJvGO_VKHyitZ8ijc_og8feRt5wAfyi8PC48/edit?usp=drivesdk | E9: Baseline taxonomy and/or current-state evidence; does not by itself prove production maturity.
A10: ERP planning / status evidence | B10: Cross-functional | C10: Erp planning final | D10: https://docs.google.com/spreadsheets/d/1umALedtbSDV1V9LXgayk7MjvL7B9ZnlNAHuD9wBdykM/edit?usp=drivesdk | E10: Timeline/status reference. Progress values should not be treated as verified process maturity without execution evidence.
A11: External reference | B11: Process taxonomy | C11: APQC Process Classification Framework (Cross Industry) | D11: https://www.apqc.org/resource-library/resource-listing/apqc-process-classification-framework-pcf-cross-industry-pdf-13 | E11: External validation for hierarchical process taxonomy and customization approach.
A12: External reference | B12: Process intelligence | C12: Microsoft Power Automate Process Mining overview | D12: https://learn.microsoft.com/en-us/power-automate/process-mining-overview | E12: External validation for event-log-based process discovery, variants, bottlenecks and automation opportunity analysis.
... A31: External reference | B31: Business Central O2C API extraction | C31: Microsoft Learn - Business Central API v2.0 / salesOrder, salesShipment, salesInvoice | D31: https://learn.microsoft.com/en-us/dynamics365/business-central/dev-itpro/api-reference/v2.0/ | E31: Validates standard REST API availability for customers and core sales-order/shipment/invoice resources; custom AGI fields still require technical schema validation.

Sheet Wave1 O2C Process Tree
A1: Process Step ID | B1: L2 Functional Wing | C1: L3 Process Group | D1: L4 Sub-process | E1: L5 Activity | F1: L6 Task / Decision | G1: Primary System | H1: System of Record | I1: Human Role | J1: Automation Mode | K1: Current State | L1: Target State | M1: Required Control | N1: Primary KPI | O1: Evidence Needed | P1: Source Title | Q1: Source URL | R1: Calibration Status
A2: O2C-001 | B2: Sales | C2: Customer & Channel Management | D2: Customer Onboarding | E2: Capture customer request | F2: Validate required fields, Customer Type, organization and territory context | G2: Sales Eco | H2: Sales Eco / BC approval status | I2: Org Admin | J2: Human + system validation | K2: Candidate S1-S2 | L2: S2 | M2: Mandatory fields; duplicate prevention; role access | N2: Digital onboarding rate | O2: Submitted customer transactions + validation/error logs | P2: BMD Sales Eco System Integration with Business Central – Solution Design | Q2: https://docs.google.com/document/d/1P3oTC3F9q076zLs0519cizrZSVzMfsoBl-hogIgGC10/edit | R2: Provisional evidence calibration complete; live production evidence pending
A3: O2C-002 | B3: Sales | C3: Customer & Channel Management | D3: Customer ERP Creation | E3: Create pending BC customer | F3: Call BC API, assign Customer No., block transactions pending approval | G3: Sales Eco + Business Central | H3: Business Central | I3: System / Finance approver | J3: Deterministic integration | K3: Candidate S2 | L3: S2 | M3: Idempotency; least-privilege integration user; audit trail | N3: Successful ERP creation rate | O3: API request/response, BC Customer record, integration log | P3: BMD Sales Eco System Integration with Business Central – Solution Design | Q3: https://docs.google.com/document/d/1P3oTC3F9q076zLs0519cizrZSVzMfsoBl-hogIgGC10/edit | R3: Provisional evidence calibration complete; live production evidence pending
A4: O2C-003 | B4: Sales / Finance | C4: Customer & Channel Management | D4: Customer Approval | E4: Approve or reject customer | F4: Review customer, approve/reject, capture reason, unblock if approved | G4: Business Central | H4: Business Central | I4: Finance / authorized approver | J4: Human approval workflow | K4: Candidate S1-S2 | L4: S2 | M4: Approval authority; blocked-until-approved; audit log | N4: Customer approval cycle time | O4: Approval entries, customer status history, approver timestamps | P4: BMD Sales Eco System Integration with Business Central – Solution Design | Q4: https://docs.google.com/document/d/1P3oTC3F9q076zLs0519cizrZSVzMfsoBl-hogIgGC10/edit | R4: Provisional evidence calibration complete; live production evidence pending
A5: O2C-004 | B5: Sales | C5: Pricing, Discount & Commercial Control | D5: Price Master Governance | E5: Create and approve price proposal | F5: Route proposal through HOD, CMO, Accounts and Management; activate approved effective price | G5: Sales Eco / ERP | H5: Approved Price Master | I5: Sales Admin, HOD, CMO, Accounts, Management | J5: Human approval + system workflow | K5: Candidate S1-S2 | L5: S2 | M5: Versioning; effective date; mandatory comments on send-back/reject | N5: Price approval cycle time | O5: Proposal versions, approval audit, activated price history | P5: Business Process Mapping Document - Primary Sales_UPDATED_SDD | Q5: https://docs.google.com/document/d/1IoV-RaOxb83z2IttGlRKy863G_pckAGUegBqnRkemgc/edit | R5: Provisional evidence calibration complete; live production evidence pending
A6: O2C-005 | B6: Sales | C6: Order Management | D6: Sales Order Intake | E6: Create customer order / sales order | F6: Select customer, item, quantity, UOM, delivery context and RC | G6: Sales Eco / Business Central | H6: Business Central for financial document | I6: Sales user | J6: Human entry + master-data validation | K6: Candidate S1-S2 | L6: S2 | M6: Active customer; valid item/UOM; valid organization/RC | N6: Order digital adoption rate | O6: Order event log, user ID, source system, timestamp | P6: Logistics Module SDD | Q6: https://docs.google.com/document/d/1doGDuain3lxIApXJtGNkRmL4FIkb1EphJ_IGoSFXJQ4/edit | R6: Provisional evidence calibration complete; live production evidence pending
A7: O2C-006 | B7: Sales / Finance | C7: Credit Management | D7: Credit Eligibility | E7: Calculate customer exposure | F7: Combine outstanding AR and pending orders; compare with customer/RC credit limit | G7: Business Central | H7: Business Central | I7: ICC / Finance | J7: Deterministic rule | K7: Candidate S2 | L7: S2 | M7: Credit limit enforced before order confirmation | N7: Credit auto-clear rate | O7: Credit limit, AR balance, pending order exposure, approval history | P7: 04.5-ACCOUNTS-FINANCE-SDD | Q7: https://docs.google.com/document/d/1opp2b-tGrMR5YcZ5IZfIjdlIIbNANJ3pPrJsKcnq5Rs/edit | R7: Provisional evidence calibration complete; live production evidence pending
A8: O2C-007 | B8: Sales / Finance | C8: Credit Management | D8: Credit Exception Approval | E8: Approve over-limit order | F8: Route exception to ICC / authorized approver based on policy | G8: Business Central | H8: Business Central | I8: ICC / Finance approver | J8: Human exception approval | K8: Candidate S1-S2 | L8: S2 | M8: No bypass; approval trail; authority limits | N8: Credit approval cycle time | O8: Approval request, decision, comments, timestamps | P8: Logistics Module SDD | Q8: https://docs.google.com/document/d/1doGDuain3lxIApXJtGNkRmL4FIkb1EphJ_IGoSFXJQ4/edit | R8: Provisional evidence calibration complete; live production evidence pending
A9: O2C-008 | B9: Sales | C9: Order Management | D9: Commercial Validation | E9: Apply price / discount | F9: Resolve standard/promotional/negotiated price and determine approval need | G9: Sales Eco / Business Central | H9: Approved Price Master / BC order | I9: Sales user / approver | J9: Rules + human exception approval | K9: Candidate S1-S2 | L9: S2 | M9: Approved price source; controlled discount threshold | N9: Manual discount exception rate | O9: Order price source, discount %, approver trail | P9: Logistics Module SDD | Q9: https://docs.google.com/document/d/1doGDuain3lxIApXJtGNkRmL4FIkb1EphJ_IGoSFXJQ4/edit | R9: Provisional evidence calibration complete; live production evidence pending
A10: O2C-009 | B10: Inventory / Sales | C10: Inventory Availability & Reservation | D10: Availability Check | E10: Check stock across warehouses | F10: Determine available/committed/reserved quantity and eligible source location | G10: Business Central | H10: Business Central | I10: System / inventory planner | J10: Deterministic rule | K10: Candidate S1-S2 | L10: S2 | M10: No negative inventory; valid warehouse/location | N10: Stock check success rate | O10: Inventory availability snapshot, reservation entries | P10: Logistics Module SDD | Q10: https://docs.google.com/document/d/1doGDuain3lxIApXJtGNkRmL4FIkb1EphJ_IGoSFXJQ4/edit | R10: Provisional evidence calibration complete; live production evidence pending
A11: O2C-010 | B11: Inventory / Sales | C11: Inventory Availability & Reservation | D11: Stock Reservation | E11: Reserve inventory | F11: Reserve stock against confirmed order and release on cancellation/expiry | G11: Business Central | H11: Business Central | I11: System | J11: Deterministic automation | K11: Candidate S2 | L11: S2 | M11: Reservation tied to confirmed order; release rule | N11: Reservation automation rate | O11: Reservation entries, release events, allocation logs | P11: Logistics Module SDD | Q11: https://docs.google.com/document/d/1doGDuain3lxIApXJtGNkRmL4FIkb1EphJ_IGoSFXJQ4/edit | R11: Provisional evidence calibration complete; live production evidence pending
A12: O2C-011 | B12: Sales / Logistics | C12: Fulfilment Coordination | D12: Delivery Order Generation | E12: Generate one or more DOs from SO | F12: Create scheduled/partial DOs while preserving parent SO and remaining balance | G12: Business Central / Logistics App | H12: Business Central | I12: Sales / logistics planner | J12: Rules + human scheduling | K12: Candidate S1-S2 | L12: S2 | M12: DO must reference SO; outstanding quantity cannot be exceeded | N12: SO-to-DO cycle time | O12: SO/DO references, quantity balances, timestamps | P12: Logistics Module SDD | Q12: https://docs.google.com/document/d/1doGDuain3lxIApXJtGNkRmL4FIkb1EphJ_IGoSFXJQ4/edit | R12: Provisional evidence calibration complete; live production evidence pending
... A30: O2C-029 | B30: Management / Cross-functional | C30: O2C Performance Management | D30: Process Monitoring | E30: Monitor end-to-end O2C performance | F30: Track throughput, cycle time, manual touches, exceptions, adoption, STP, OTIF and DSO | G30: Fabric / Power BI / process intelligence | H30: Event data from systems of record | I30: Process owner / management | J30: Analytics / process mining | K30: TBD | L30: S3 | M30: KPI lineage; common process IDs; verified event timestamps | N30: O2C end-to-end cycle time | O30: Event log across customer/order/delivery/invoice/payment | P30: Microsoft Power Automate Process Mining overview | Q30: https://learn.microsoft.com/en-us/power-automate/process-mining-overview | R30: Provisional evidence calibration complete; live production evidence pending

Sheet O2C Metric Dictionary
A1: Metric ID | B1: Metric Name | C1: KPI Family | D1: Definition | E1: Formula / Calculation | F1: Numerator | G1: Denominator | H1: Unit | I1: Grain | J1: Source Event / System | K1: Management Use | L1: Proposed Direction / Target | M1: Status
A2: M-O2C-01 | B2: O2C End-to-End Cycle Time | C2: Process Performance | D2: Elapsed time from accepted customer order to cash application/closure. | E2: Average(cash application timestamp - order accepted timestamp) | F2: N/A | G2: N/A | H2: Hours / days | I2: Order / customer / SBU | J2: Sales Eco + BC + Logistics event timestamps | K2: Shows total working-capital and service latency. | L2: Reduce vs verified baseline; no numeric target until calibrated | M2: Definition proposed
A3: M-O2C-02 | B3: Order Digital Adoption Rate | C3: Adoption | D3: Share of eligible customer orders initiated and processed through the approved digital process. | E3: Digital orders / total eligible orders | F3: Orders executed through approved system | G3: All eligible orders | H3: % | I3: SBU / channel / month | J3: Sales Eco / BC order sources | K3: Detects shadow/manual order processes. | L3: Increase toward 100%; target to be calibrated | M3: Definition proposed
A4: M-O2C-03 | B4: Human Touches per Order | C4: Human Dependency | D4: Count of distinct human actions required from order intake through cash application. | E4: Human action events / completed orders | F4: Count of human action events | G4: Completed O2C orders | H4: Touches / order | I4: Order / process step | J4: Workflow/audit logs across Sales Eco, BC, Logistics | K4: Quantifies manual reliance and automation opportunity. | L4: Reduce where controls permit | M4: Requires event classification
A5: M-O2C-04 | B5: Human Minutes per Order | C5: Human Dependency | D5: Estimated or measured active human processing time across the O2C chain. | E5: Sum active human processing minutes / completed orders | F5: Active human minutes | G5: Completed orders | H5: Minutes / order | I5: Order / role / activity | J5: Task timestamps, time study, workflow logs | K5: Supports productivity and benefit realization. | L5: Reduce vs baseline without weakening controls | M5: Requires baseline study
A6: M-O2C-05 | B6: Straight-Through Processing Rate | C6: Automation | D6: Share of eligible transactions completed through the defined scope without manual intervention. | E6: Transactions completed without manual intervention / eligible transactions | F6: No-manual-intervention transactions | G6: Eligible transactions | H6: % | I6: Process / SBU / transaction type | J6: Cross-system event log | K6: Core indicator of deterministic automation. | L6: Increase only for low-risk standardized cases | M6: Definition proposed
A7: M-O2C-06 | B7: Credit Auto-Clear Rate | C7: Automation / Control | D7: Share of eligible orders that pass credit validation without manual exception approval. | E7: Credit-cleared orders without manual approval / credit-checked orders | F7: Auto-cleared orders | G7: Credit-checked orders | H7: % | I7: Customer / RC / SBU | J7: BC credit check / approval events | K7: Shows effectiveness of standard credit rules. | L7: Increase for policy-compliant orders | M7: Definition proposed
A8: M-O2C-07 | B8: Credit Exception Rate | C8: Exception | D8: Share of credit-checked orders requiring override or exception approval. | E8: Credit exception orders / credit-checked orders | F8: Exception orders | G8: Credit-checked orders | H8: % | I8: Customer / RC / SBU | J8: BC approval workflow | K8: Highlights policy friction and customer-risk exposure. | L8: Reduce avoidable exceptions; do not suppress justified approvals | M8: Definition proposed
A9: M-O2C-08 | B9: Credit Approval Cycle Time | C9: Process Performance | D9: Elapsed time from credit exception submission to final approval/rejection. | E9: Average(decision timestamp - submission timestamp) | F9: N/A | G9: N/A | H9: Minutes / hours | I9: Exception / approver / SBU | J9: BC approval workflow | K9: Finds approval bottlenecks. | L9: Reduce vs baseline; design SDD references <4 hours as a candidate benchmark, not verified target | M9: Target requires management validation
A10: M-O2C-09 | B10: Manual Discount Exception Rate | C10: Exception / Commercial Control | D10: Share of orders requiring non-standard discount approval. | E10: Orders with discount exception / total eligible orders | F10: Discount-exception orders | G10: Eligible orders | H10: % | I10: SBU / customer / product | J10: Sales Eco / BC pricing and approval events | K10: Identifies pricing-policy leakage and process friction. | L10: Reduce avoidable exceptions; preserve approved commercial flexibility | M10: Definition proposed
A11: M-O2C-10 | B11: Stock Availability Pass Rate | C11: Fulfilment | D11: Share of order lines that can be fulfilled from eligible stock when checked. | E11: Lines passing availability check / lines checked | F11: Available order lines | G11: Lines checked | H11: % | I11: Item / location / SBU | J11: Business Central inventory availability | K11: Links inventory readiness to sales service. | L11: Increase; segment by stockout cause | M11: Definition proposed
A12: M-O2C-11 | B12: Reservation Automation Rate | C12: Automation | D12: Share of eligible confirmed order lines reserved automatically without manual allocation. | E12: Automatically reserved lines / eligible confirmed lines | F12: Automatically reserved lines | G12: Eligible confirmed lines | H12: % | I12: Item / location / SBU | J12: BC reservation entries | K12: Measures inventory-fulfilment automation. | L12: Increase for standard allocation cases | M12: Definition proposed
... A34: M-O2C-33 | B34: Digital Receipt Rate | C34: Adoption / Control | D34: Share of eligible customer receipts captured through the approved digital Money Receipt/receipt process with authoritative ERP linkage. | E34: Digitally captured and ERP-linked receipts / eligible customer receipts | F34: Receipts with approved digital source and ERP posting/reference | G34: Eligible customer receipts | H34: % | I34: SBU / bank / customer / month | J34: Sales Eco MR + Business Central receipt/ledger entries | K34: Detects off-system receipt capture and reconciliation risk. | L34: Increase toward 100% where digital receipt is mandatory | M34: Definition proposed; baseline pending

Sheet O2C Evidence Requirements
A1: Evidence ID | B1: Process Step / Area | C1: Evidence Level Supported | D1: Evidence Artifact | E1: System / Owner | F1: Required Fields | G1: Sampling Window / Frequency | H1: Validation Test | I1: Failure Signal | J1: Management Interpretation | K1: Source / URL | L1: Status
A2: EV-O2C-01 | B2: Entire O2C design baseline | C2: E1 | D2: Approved SDD/FRD/SOP and signed requirements | E2: Process owner / AESL / implementation team | F2: Process scope, actors, business rules, approvals, integrations, exceptions, target behavior | G2: Latest approved version; review on material change | H2: Confirm document approval/version and map each L4-L6 step to supporting requirement | I2: Unapproved draft; conflicting documents; missing process step | J2: Proves intended design only, not production maturity | K2: https://docs.google.com/document/d/1IoV-RaOxb83z2IttGlRKy863G_pckAGUegBqnRkemgc/edit | L2: Available; needs evidence mapping
A3: EV-O2C-02 | B3: Customer onboarding / approval | C3: E2-E3 | D3: Sales Eco and BC configuration plus production customer approval history | E3: Sales / Finance / system owner | F3: Customer ID, organization, type, status, BC Customer No., blocked state, approver, decision, timestamps | G3: Sample recent 30-90 days across active SBUs | H3: Trace submitted customer through BC creation, approval/rejection and callback | I3: Missing BC reference; unblocked before approval; approval outside system | J3: Distinguishes configured onboarding from actually governed digital onboarding | K3: https://docs.google.com/document/d/1P3oTC3F9q076zLs0519cizrZSVzMfsoBl-hogIgGC10/edit | L3: Pending production sample
A4: EV-O2C-03 | B4: Price / discount governance | C4: E2-E4 | D4: Price proposal configuration, version history and approval events | E4: Sales / Commercial | F4: Price proposal ID, item/customer scope, old/new price, effective date, approver chain, comments, activated version | G4: Recent 3 months and latest price change by SBU | H4: Reconcile approved version to price used on orders | I4: Order price not traceable to approved master; offline discount approval | J4: Supports pricing control, exception rate and cycle-time metrics | K4: https://docs.google.com/document/d/1IoV-RaOxb83z2IttGlRKy863G_pckAGUegBqnRkemgc/edit | L4: Pending configuration/event evidence
A5: EV-O2C-04 | B5: Order intake | C5: E3-E4 | D5: Production customer order / sales order event extract | E5: Sales Eco / Business Central | F5: Order ID, source, creator, customer, item, qty, UOM, RC, created/submitted/approved timestamps, status | G5: At least 30 days; preferably 90 days including all active SBUs | H5: Compare transaction counts to known/manual order population and identify off-system orders | I5: Missing source tag; duplicate orders; material manual order population | J5: Required to measure digital adoption and order cycle time | K5: https://learn.microsoft.com/en-us/dynamics365/business-central/quick-start-sell-products-and-services | L5: Pending production extract
A6: EV-O2C-05 | B6: Credit control | C6: E3-E4 | D6: Credit-check and approval workflow event log | E6: Business Central / Finance | F6: Customer, RC, credit limit, AR exposure, pending order exposure, decision, exception reason, approver, timestamps | G6: 30-90 days by SBU/RC | H6: Recalculate exposure for sample orders and verify approval only when rule requires | I6: Credit bypass; stale exposure; approval missing; approval outside system | J6: Supports auto-clear, exception, approval-time and control-effectiveness measures | K6: https://docs.google.com/document/d/1opp2b-tGrMR5YcZ5IZfIjdlIIbNANJ3pPrJsKcnq5Rs/edit | L6: Pending production extract
A7: EV-O2C-06 | B7: Stock availability / reservation | C7: E3-E4 | D7: Inventory availability snapshots and reservation entries linked to sales orders | E7: Business Central / Inventory | F7: SO line, item, location, on-hand, available, reserved, reservation timestamp, release reason | G7: 30-90 days; sample stockout and cancellation cases | H7: Trace selected order lines from availability check through reservation/release | I7: Negative stock; reservation absent; manual allocation with no record; stale availability | J7: Proves actual inventory automation and fulfilment readiness | K7: https://docs.google.com/document/d/1eGvAn9ZvGrCKaBnvot_iqCkITzAsJlsNsOteIiyCT58/edit | L7: Pending production extract
A8: EV-O2C-07 | B8: SO to DO linkage | C8: E3-E4 | D8: Sales Order / Delivery Order cross-reference extract | E8: Business Central / Logistics | F8: SO No., DO No., order qty, DO qty, delivered qty, outstanding qty, creation/status timestamps | G8: 90-day sample including partial/scheduled deliveries | H8: Confirm every DO references one valid SO and cumulative DO quantity does not exceed eligible balance | I8: Orphan DO; broken quantity balance; duplicate allocation | J8: Foundation for partial-delivery monitoring and O2C reconciliation | K8: https://learn.microsoft.com/en-us/dynamics365/business-central/sales-how-send-partial-shipments | L8: Pending production extract
A9: EV-O2C-08 | B9: Trip planning / vehicle allocation | C9: E2-E4 | D9: Trip, DO membership, route and vehicle/driver assignment log | E9: Logistics App / Logistics owner | F9: Trip ID, DO IDs, stops, vehicle, capacity, driver, eligibility checks, assignment time, override reason | G9: 30-60 days across own/hired vehicles | H9: Verify capacity/document/driver eligibility and reconstruct manual overrides | I9: Allocation outside app; missing capacity checks; invalid driver/vehicle docs | J9: Determines actual transition from spreadsheet/phone planning to digital execution | K9: https://docs.google.com/document/d/1doGDuain3lxIApXJtGNkRmL4FIkb1EphJ_IGoSFXJQ4/edit | L9: Pending production evidence
A10: EV-O2C-09 | B10: Loading execution | C10: E3-E4 | D10: Loading advice and actual loading events | E10: Logistics / Warehouse | F10: DO, item, advised qty, loaded qty, discrepancy reason, user, timestamps | G10: 30-60 days; include discrepancy cases | H10: Reconcile loaded quantity to authorized DO and subsequent DN/shipment | I10: Paper-only loading; unexplained variance; loaded quantity exceeds authorization | J10: Supports loading accuracy and human-touch analysis | K10: https://docs.google.com/document/d/1doGDuain3lxIApXJtGNkRmL4FIkb1EphJ_IGoSFXJQ4/edit | L10: Pending production evidence
A11: EV-O2C-10 | B11: Gate / weighbridge | C11: E3-E4 | D11: Digital gate-in, weighbridge and gate-out events | E11: Gate / Logistics | F11: Trip, vehicle, gate-in/out timestamps, gross/tare/net if applicable, gate document status | G11: 30-60 days by plant | H11: Match gate-out to valid loaded trip; calculate dwell; inspect missing/duplicate events | I11: Paper register only; missing timestamp; gate-out before loading completion | J11: Proves gate-control digitization and identifies plant congestion | K11: https://docs.google.com/document/d/1doGDuain3lxIApXJtGNkRmL4FIkb1EphJ_IGoSFXJQ4/edit | L11: Pending production evidence
A12: EV-O2C-11 | B12: Dispatch / in-transit | C12: E3-E4 | D12: Shipment status history and GPS/telemetry where implemented | E12: Logistics App | F12: Trip, dispatch time, status transitions, route/ETA, location events, exception events | G12: 30-60 days | H12: Check sequence/timestamps and compare dispatch schedule to actual departure | I12: Status entered retrospectively; missing location/status history | J12: Supports dispatch punctuality and actual execution visibility | K12: https://docs.google.com/document/d/1doGDuain3lxIApXJtGNkRmL4FIkb1EphJ_IGoSFXJQ4/edit | L12: Pending production evidence
... A22: EV-O2C-21 | B22: Transformation outcome verification | C22: E5 | D22: Approved baseline vs post-change KPI and benefit pack | E22: Business process owner / Finance / Transformation Office | F22: Baseline period, post-change period, volume normalization, KPI change, human hours saved, cost/value, controls, adoption, assumptions | G22: Per initiative; 30/60/90-day post-go-live and quarterly thereafter | H22: Verify same process scope, comparable volume/mix, attributable change and finance sign-off for monetary benefits | I22: Claimed benefit with no baseline; volume/mix distortion; savings not realized operationally | J22: Only E5 should be treated as realized transformation value | K22: https://learn.microsoft.com/en-us/power-automate/process-mining-overview | L22: Not available yet

Sheet Wave2 S2P Process Tree
A1: Process Step ID | B1: L2 Functional Wing | C1: L3 Process Group | D1: L4 Sub-process | E1: L5 Activity | F1: L6 Task / Decision | G1: Primary System | H1: System of Record | I1: Human Role | J1: Automation Mode | K1: Current State | L1: Target State | M1: Required Control | N1: Primary KPI | O1: Evidence Needed | P1: Source Title | Q1: Source URL | R1: Calibration Status
A2: S2P-001 | B2: SCM / Requesting Function | C2: Demand Management | D2: Demand Capture | E2: Create internal demand | F2: Capture requester, item/service, quantity, need date, purpose, priority, cost center and attachments | G2: Custom Demand / Business Central | H2: Approved demand record | I2: Requester | J2: Human entry + system validation | K2: Candidate S0-S1 | L2: S1/S2 | M2: Mandatory fields; role access; valid master data; duplicate prevention | N2: Demand digital adoption rate | O2: Demand records, source channel, user, timestamps, validation errors | P2: SCM - Signed SDD + SCM Business Central Project Annexes | Q2: https://docs.google.com/document/d/127YQA_Z0zcKBMCFBa4ZgW_kmnExCMgfpheJ_DeoXFmw/edit | R2: Not calibrated
A3: S2P-002 | B3: SCM / Inventory / Planning | C3: Demand Management | D3: Automatic Demand Generation | E3: Generate replenishment demand | F3: Use reorder points, inventory position, sales forecasts and manufacturing plans to suggest demand | G3: Business Central Requisition Worksheet / extension | H3: Business Central planning data | I3: Inventory Planner | J3: Deterministic planning rule + human review | K3: Candidate S1-S2 | L3: S2 | M3: Approved planning parameters; demand traceability; exception override reason | N3: Auto-demand generation rate | O3: Requisition worksheet suggestions, reorder parameters, acceptance/rejection events | P3: SCM - Signed SDD + Microsoft purchasing/planning guidance | Q3: https://learn.microsoft.com/en-us/dynamics365/business-central/planning-supply | R3: Not calibrated
A4: S2P-003 | B4: SCM / Requesting Function | C4: Demand Management | D4: Demand Approval | E4: Approve or reject demand | F4: Route demand/requisition to authorized approver based on policy, category, value and cost center | G4: Business Central Workflow / Custom Demand | H4: Business Central approval entry | I4: Department / Budget Approver | J4: Human approval workflow | K4: Candidate S1-S2 | L4: S2 | M4: No self-approval; delegated authority; comments/rejection reason; audit trail | N4: Demand approval cycle time | O4: Approval requests, decisions, delegation, comments, timestamps | P4: SCM Business Central Project Annexes - UAT / Fit-Gap | Q4: https://docs.google.com/spreadsheets/d/1laHtFEUFbm3VAheUpIXssk8dKZ9sCiNyWZ7nC5wg9Es/edit | R4: Not calibrated
